<?xml version="1.0" ?>
<sdf version="1.8">
  <model name="prius_hybridx">
    <pose>0 0 0.03 0 0 0</pose>

    <link name="chassis">
      <inertial>
        <mass>1326.0</mass>
        <pose>0 -0.266 0.48 0 0 0</pose>
        <inertia>
          <ixx>2581.13354740</ixx>
          <ixy>0.0</ixy>
          <iyy>591.30846112</iyy>
          <ixz>0.0</ixz>
          <iyz>0.0</iyz>
          <izz>2681.95008628</izz>
        </inertia>
      </inertial>

      <visual name="chassis_visual">
        <geometry>
          <mesh>
            <uri>model://prius_hybrid/meshes/Hybrid.obj</uri>
            <scale>0.01 0.01 0.01</scale>
            <submesh>
              <name>Hybrid</name>
              <center>false</center>
            </submesh>
          </mesh>
        </geometry>
      </visual>

      <visual name="interior_visual">
        <geometry>
          <mesh>
            <uri>model://prius_hybrid/meshes/Hybrid.obj</uri>
            <scale>0.01 0.01 0.01</scale>
            <submesh>
              <name>Hybrid_Interior</name>
              <center>false</center>
            </submesh>
          </mesh>
        </geometry>
      </visual>

      <visual name="windows_visual">
        <geometry>
          <mesh>
            <uri>model://prius_hybrid/meshes/Hybrid.obj</uri>
            <scale>0.01 0.01 0.01</scale>
            <submesh>
              <name>Hybrid_Windows</name>
              <center>false</center>
            </submesh>
          </mesh>
        </geometry>
      </visual>

      <collision name="chassis">
        <pose>0.0 0.05 0.625 0 0 0</pose>
        <geometry>
          <box>
            <size>1.7526 2.1 0.95</size>
          </box>
        </geometry>
      </collision>

      <collision name="front_bumper">
        <pose>0.0 -2.0 0.458488 0.0 0 0</pose>
        <geometry>
          <box>
            <size>1.337282 0.48 0.566691</size>
          </box>
        </geometry>
      </collision>

      <collision name="hood">
        <pose>0.0 -1.900842 0.676305 0.341247 0 0</pose>
        <geometry>
          <box>
            <size>1.597968 0.493107 0.265468</size>
          </box>
        </geometry>
      </collision>

      <collision name="windshield">
        <pose>0.0 -0.875105 1.032268 0.335476 0 0</pose>
        <geometry>
          <box>
            <size>1.168381 1.654253 0.272347</size>
          </box>
        </geometry>
      </collision>

      <collision name="top_front">
        <pose>0.0 0.161236 1.386042 0.135030 0 0</pose>
        <geometry>
          <box>
            <size>1.279154 0.625988 0.171868</size>
          </box>
        </geometry>
      </collision>

      <collision name="top_rear">
        <pose>0.0 0.817696 1.360069 -0.068997 0 0</pose>
        <geometry>
          <box>
            <size>1.285130 0.771189 0.226557</size>
          </box>
        </geometry>
      </collision>

      <collision name="rear_window">
        <pose>0.0 1.640531 1.175126 -0.262017 0 0</pose>
        <geometry>
          <box>
            <size>1.267845 1.116344 0.244286</size>
          </box>
        </geometry>
      </collision>

      <collision name="trunk">
        <pose>0.0 1.637059 0.888180 0.0 0 0</pose>
        <geometry>
          <box>
            <size>1.788064 1.138988 0.482746</size>
          </box>
        </geometry>
      </collision>

      <collision name="back_bumper">
        <pose>0.0 2.054454 0.577870 0.0 0 0</pose>
        <geometry>
          <box>
            <size>1.781650 0.512093 0.581427</size>
          </box>
        </geometry>
      </collision>
    </link>

    <link name="front_left_wheel">
      <pose>0.76 -1.41 0.3 0 0 0</pose>
      <inertial>
        <mass>11</mass>
        <inertia>
          <ixx>0.58631238</ixx>
          <ixy>0.0</ixy>
          <iyy>0.33552910</iyy>
          <ixz>0.0</ixz>
          <iyz>0.0</iyz>
          <izz>0.33552910</izz>
        </inertia>
      </inertial>

      <visual name="visual">
        <pose>0.04 0.0 0.0 0 0 0</pose>
        <geometry>
          <mesh>
            <uri>model://prius_hybrid/meshes/Hybrid.obj</uri>
            <scale>0.01 0.01 0.01</scale>
            <submesh>
              <name>Wheel_Front_Left_</name>
              <center>true</center>
            </submesh>
          </mesh>
        </geometry>
      </visual>

      <collision name="collision">
        <pose>0.0 0.0 0.0 0 1.5707963267948966 0</pose>
        <geometry>
          <sphere>
            <radius>0.31265</radius>
          </sphere>
        </geometry>
        <surface>
          <friction>
            <ode>
              <mu>0.9</mu>
              <mu2>0.9</mu2>
              <slip1>0.0</slip1>
              <slip2>0.0</slip2>
            </ode>
          </friction>
          <contact>
            <ode>
              <min_depth>0.001</min_depth>
              <kp>1e9</kp>
            </ode>
          </contact>
        </surface>
      </collision>
      
      <sensor name="imu_sensor" type="imu">
        <always_on>1</always_on>
        <update_rate>250</update_rate>
        <imu>
          <angular_velocity>
            <x>
              <noise type="gaussian">
                <mean>0</mean>
                <stddev>0.00018665</stddev>
                <dynamic_bias_stddev>3.8785e-05</dynamic_bias_stddev>
                <dynamic_bias_correlation_time>1000</dynamic_bias_correlation_time>
              </noise>
            </x>
            <y>
              <noise type="gaussian">
                <mean>0</mean>
                <stddev>0.00018665</stddev>
                <dynamic_bias_stddev>3.8785e-05</dynamic_bias_stddev>
                <dynamic_bias_correlation_time>1000</dynamic_bias_correlation_time>
              </noise>
            </y>
            <z>
              <noise type="gaussian">
                <mean>0</mean>
                <stddev>0.00018665</stddev>
                <dynamic_bias_stddev>3.8785e-05</dynamic_bias_stddev>
                <dynamic_bias_correlation_time>1000</dynamic_bias_correlation_time>
              </noise>
            </z>
          </angular_velocity>
          <linear_acceleration>
            <x>
              <noise type="gaussian">
                <mean>0</mean>
                <stddev>0.00186</stddev>
                <dynamic_bias_stddev>0.006</dynamic_bias_stddev>
                <dynamic_bias_correlation_time>300</dynamic_bias_correlation_time>
              </noise>
            </x>
            <y>
              <noise type="gaussian">
                <mean>0</mean>
                <stddev>0.00186</stddev>
                <dynamic_bias_stddev>0.006</dynamic_bias_stddev>
                <dynamic_bias_correlation_time>300</dynamic_bias_correlation_time>
              </noise>
            </y>
            <z>
              <noise type="gaussian">
                <mean>0</mean>
                <stddev>0.00186</stddev>
                <dynamic_bias_stddev>0.006</dynamic_bias_stddev>
                <dynamic_bias_correlation_time>300</dynamic_bias_correlation_time>
              </noise>
            </z>
          </linear_acceleration>
        </imu>
      </sensor>
      
      <sensor name="navsat_sensor" type="navsat">
        <always_on>1</always_on>
        <update_rate>30</update_rate>
      </sensor>
    </link>

    <link name="front_left_wheel_steering">
      <pose relative_to="front_left_wheel_joint">0 0 0 0 0 0</pose>
      <inertial>
        <mass>1.0</mass>
        <inertia>
          <ixx>0.14583300</ixx>
          <ixy>0</ixy>
          <ixz>0</ixz>
          <iyy>0.14583300</iyy>
          <iyz>0</iyz>
          <izz>0.12500000</izz>
        </inertia>
      </inertial>
    </link>

    <joint name="front_left_wheel_joint" type="revolute" >
      <pose relative_to="front_left_wheel">0 0 0 0 0 0</pose>
      <child>front_left_wheel</child>
      <parent>front_left_wheel_steering</parent>
      <axis>
        <xyz>1 0 0</xyz>
        <limit>
          <lower>-1.79769e+308</lower>
          <upper>1.79769e+308</upper>
        </limit>
        <dynamics>
          <spring_reference>0</spring_reference>
          <spring_stiffness>0</spring_stiffness>
        </dynamics>
        <!-- <use_parent_model_frame>true</use_parent_model_frame> -->
      </axis>
    </joint>

    <joint name="front_left_wheel_steering_joint" type="revolute">
      <pose relative_to="front_left_wheel_steering">0 0 0 0 0 0</pose>
      <parent>chassis</parent>
      <child>front_left_wheel_steering</child>
      <axis>
        <xyz>0 0 1</xyz>
        <limit>
          <lower>-0.6</lower>
          <upper>0.6</upper>
          <velocity>1.0</velocity>
          <effort>25</effort>
        </limit>
        <!-- <use_parent_model_frame>true</use_parent_model_frame> -->
      </axis>
    </joint>

    <link name="front_right_wheel">
      <pose>-0.76 -1.41 0.3 0 0 0</pose>
      <inertial>
        <mass>11</mass>
        <inertia>
          <ixx>0.58631238</ixx>
          <ixy>0.0</ixy>
          <iyy>0.33552910</iyy>
          <ixz>0.0</ixz>
          <iyz>0.0</iyz>
          <izz>0.33552910</izz>
        </inertia>
      </inertial>
      <visual name="visual">
        <pose>-0.04 0.0 0.0 0 0 0</pose>
        <pose>0 0 0.0 0 0 0</pose>
        <geometry>
          <mesh>
            <uri>model://prius_hybrid/meshes/Hybrid.obj</uri>
            <scale>0.01 0.01 0.01</scale>
            <submesh>
              <name>Wheel_Front_Right</name>
              <center>true</center>
            </submesh>
          </mesh>
        </geometry>
      </visual>

      <collision name="collision">
        <pose>0.0 0.0 0.0 0 1.5707963267948966 0</pose>
        <geometry>
          <sphere>
            <radius>0.31265</radius>
          </sphere>
        </geometry>
        <surface>
          <friction>
            <ode>
              <mu>0.9</mu>
              <mu2>0.9</mu2>
              <slip1>0.0</slip1>
              <slip2>0.0</slip2>
            </ode>
          </friction>
          <contact>
            <ode>
              <min_depth>0.001</min_depth>
              <kp>1e9</kp>
            </ode>
          </contact>
        </surface>

      </collision>
    </link>

    <link name="front_right_wheel_steering">
      <pose relative_to="front_right_wheel_joint">0 0 0 0 0 0</pose>
      <inertial>
        <mass>1.0</mass>
        <inertia>
          <ixx>0.14583300</ixx>
          <ixy>0</ixy>
          <ixz>0</ixz>
          <iyy>0.14583300</iyy>
          <iyz>0</iyz>
          <izz>0.12500000</izz>
        </inertia>
      </inertial>
    </link>

    <joint name="front_right_wheel_joint" type="revolute" >
      <pose relative_to="front_right_wheel">0 0 0 0 0 0</pose>
      <child>front_right_wheel</child>
      <parent>front_right_wheel_steering</parent>
      <axis>
        <xyz>1 0 0</xyz>
        <limit>
          <lower>-1.79769e+308</lower>
          <upper>1.79769e+308</upper>
        </limit>
        <dynamics>
          <spring_reference>0</spring_reference>
          <spring_stiffness>0</spring_stiffness>
        </dynamics>
        <!-- <use_parent_model_frame>true</use_parent_model_frame> -->
      </axis>
    </joint>

    <joint name="front_right_wheel_steering_joint" type="revolute">
      <pose relative_to="front_right_wheel_steering">0 0 0 0 0 0</pose>
      <parent>chassis</parent>
      <child>front_right_wheel_steering</child>
      <axis>
        <xyz>0 0 1</xyz>
        <limit>
          <lower>-0.6</lower>
          <upper>0.6</upper>
          <velocity>1.0</velocity>
          <effort>25</effort>
        </limit>
        <!-- <use_parent_model_frame>true</use_parent_model_frame> -->
      </axis>
    </joint>

    <link name="rear_left_wheel">
      <pose>0.786 1.45 0.3 0 0 0</pose>
      <inertial>
        <mass>11</mass>
        <inertia>
          <ixx>0.58631238</ixx>
          <ixy>0.0</ixy>
          <iyy>0.33552910</iyy>
          <ixz>0.0</ixz>
          <iyz>0.0</iyz>
          <izz>0.33552910</izz>
        </inertia>
      </inertial>

      <visual name="visual">
        <pose>0.04 0.0 0.0 0 0 0</pose>
        <geometry>
          <mesh>
            <uri>model://prius_hybrid/meshes/Hybrid.obj</uri>
            <scale>0.01 0.01 0.01</scale>
            <submesh>
              <name>Wheel_Front_Left_</name>
              <center>true</center>
            </submesh>
          </mesh>
        </geometry>
      </visual>

      <collision name="collision">
        <pose>0.0 0.0 0.0 0 1.5707963267948966 0</pose>
        <geometry>
          <sphere>
            <radius>0.31265</radius>
          </sphere>
        </geometry>
        <surface>
          <friction>
            <ode>
              <mu>1.1</mu>
              <mu2>1.1</mu2>
              <slip1>0.0</slip1>
              <slip2>0.0</slip2>
            </ode>
          </friction>
          <contact>
            <ode>
              <min_depth>0.001</min_depth>
              <kp>1e9</kp>
            </ode>
          </contact>
        </surface>

      </collision>
    </link>

    <joint name="rear_left_wheel_joint" type="revolute">
      <parent>chassis</parent>
      <child>rear_left_wheel</child>
      <pose relative_to="rear_left_wheel">0 0 0 0 0 0</pose>
      <axis>
        <xyz>1 0 0</xyz>
        <limit>
          <lower>-1.79769e+308</lower>
          <upper>1.79769e+308</upper>
        </limit>
        <dynamics>
          <spring_reference>0</spring_reference>
          <spring_stiffness>0</spring_stiffness>
        </dynamics>
        <!-- <use_parent_model_frame>true</use_parent_model_frame> -->
      </axis>
    </joint>

    <link name="rear_right_wheel">
      <pose>-0.786 1.45 0.3 0 0 0</pose>
      <inertial>
        <mass>11</mass>
        <inertia>
          <ixx>0.58631238</ixx>
          <ixy>0.0</ixy>
          <iyy>0.33552910</iyy>
          <ixz>0.0</ixz>
          <iyz>0.0</iyz>
          <izz>0.33552910</izz>
        </inertia>
      </inertial>
      <visual name="visual">
        <pose>-0.04 0.0 0.0 0 0 0</pose>
        <geometry>
          <mesh>
            <uri>model://prius_hybrid/meshes/Hybrid.obj</uri>
            <scale>0.01 0.01 0.01</scale>
            <submesh>
              <name>Wheel_Front_Right</name>
              <center>true</center>
            </submesh>
          </mesh>
        </geometry>
      </visual>

      <collision name="collision">
        <pose>0.0 0.0 0.0 0 1.5707963267948966 0</pose>
        <geometry>
          <sphere>
            <radius>0.31265</radius>
          </sphere>
        </geometry>
        <surface>
          <friction>
            <ode>
              <mu>1.1</mu>
              <mu2>1.1</mu2>
              <slip1>0.0</slip1>
              <slip2>0.0</slip2>
            </ode>
          </friction>
          <contact>
            <ode>
              <min_depth>0.001</min_depth>
              <kp>1e9</kp>
            </ode>
          </contact>
        </surface>
      </collision>
    </link>

    <joint name="rear_right_wheel_joint" type="revolute">
      <parent>chassis</parent>
      <child>rear_right_wheel</child>
      <pose relative_to="rear_right_wheel">0 0 0 0 0 0</pose>
      <axis>
        <xyz>1 0 0</xyz>
        <limit>
          <lower>-1.79769e+308</lower>
          <upper>1.79769e+308</upper>
        </limit>
        <dynamics>
          <spring_reference>0</spring_reference>
          <spring_stiffness>0</spring_stiffness>
        </dynamics>
        <!-- <use_parent_model_frame>true</use_parent_model_frame> -->
      </axis>
    </joint>
    
  </model>

</sdf>
